[2025-02-21T13:39:37.758+0000] {local_task_job_runner.py:123} INFO - ::group::Pre task execution logs
[2025-02-21T13:39:37.781+0000] {taskinstance.py:2614} INFO - Dependencies all met for dep_context=non-requeueable deps ti=<TaskInstance: ing_mov_20_21.run_spark_script manual__2025-02-21T13:39:36.308237+00:00 [queued]>
[2025-02-21T13:39:37.791+0000] {taskinstance.py:2614} INFO - Dependencies all met for dep_context=requeueable deps ti=<TaskInstance: ing_mov_20_21.run_spark_script manual__2025-02-21T13:39:36.308237+00:00 [queued]>
[2025-02-21T13:39:37.791+0000] {taskinstance.py:2867} INFO - Starting attempt 1 of 2
[2025-02-21T13:39:37.813+0000] {taskinstance.py:2890} INFO - Executing <Task(DockerOperator): run_spark_script> on 2025-02-21 13:39:36.308237+00:00
[2025-02-21T13:39:37.817+0000] {warnings.py:112} WARNING - /home/***/.local/lib/python3.12/site-packages/***/task/task_runner/standard_task_runner.py:70: DeprecationWarning: This process (pid=198) is multi-threaded, use of fork() may lead to deadlocks in the child.
  pid = os.fork()

[2025-02-21T13:39:37.818+0000] {standard_task_runner.py:72} INFO - Started process 199 to run task
[2025-02-21T13:39:37.819+0000] {standard_task_runner.py:104} INFO - Running: ['***', 'tasks', 'run', 'ing_mov_20_21', 'run_spark_script', 'manual__2025-02-21T13:39:36.308237+00:00', '--job-id', '9', '--raw', '--subdir', 'DAGS_FOLDER/scriptteste.py', '--cfg-path', '/tmp/tmp9_q5pu9p']
[2025-02-21T13:39:37.821+0000] {standard_task_runner.py:105} INFO - Job 9: Subtask run_spark_script
[2025-02-21T13:39:37.881+0000] {task_command.py:467} INFO - Running <TaskInstance: ing_mov_20_21.run_spark_script manual__2025-02-21T13:39:36.308237+00:00 [running]> on host 184127898c48
[2025-02-21T13:39:37.984+0000] {taskinstance.py:3134} INFO - Exporting env vars: AIRFLOW_CTX_DAG_OWNER='***' AIRFLOW_CTX_DAG_ID='ing_mov_20_21' AIRFLOW_CTX_TASK_ID='run_spark_script' AIRFLOW_CTX_EXECUTION_DATE='2025-02-21T13:39:36.308237+00:00' AIRFLOW_CTX_TRY_NUMBER='1' AIRFLOW_CTX_DAG_RUN_ID='manual__2025-02-21T13:39:36.308237+00:00'
[2025-02-21T13:39:37.985+0000] {taskinstance.py:732} INFO - ::endgroup::
[2025-02-21T13:39:38.022+0000] {docker.py:157} ERROR - Failed to establish connection to Docker host unix://var/run/docker.sock: Error while fetching server API version: ('Connection aborted.', FileNotFoundError(2, 'No such file or directory'))
[2025-02-21T13:39:38.033+0000] {taskinstance.py:3313} ERROR - Task failed with exception
Traceback (most recent call last):
  File "/home/airflow/.local/lib/python3.12/site-packages/airflow/models/taskinstance.py", line 768, in _execute_task
    result = _execute_callable(context=context, **execute_callable_kwargs)
             ^^^^^^^^^^^^^^^^^^^^^^^^^^^^^^^^^^^^^^^^^^^^^^^^^^^^^^^^^^^^^
  File "/home/airflow/.local/lib/python3.12/site-packages/airflow/models/taskinstance.py", line 734, in _execute_callable
    return ExecutionCallableRunner(
           ^^^^^^^^^^^^^^^^^^^^^^^^
  File "/home/airflow/.local/lib/python3.12/site-packages/airflow/utils/operator_helpers.py", line 252, in run
    return self.func(*args, **kwargs)
           ^^^^^^^^^^^^^^^^^^^^^^^^^^
  File "/home/airflow/.local/lib/python3.12/site-packages/airflow/models/baseoperator.py", line 424, in wrapper
    return func(self, *args, **kwargs)
           ^^^^^^^^^^^^^^^^^^^^^^^^^^^
  File "/home/airflow/.local/lib/python3.12/site-packages/airflow/providers/docker/operators/docker.py", line 467, in execute
    if self.force_pull or not self.cli.images(name=self.image):
                              ^^^^^^^^
  File "/home/airflow/.local/lib/python3.12/site-packages/airflow/providers/docker/operators/docker.py", line 341, in cli
    return self.hook.api_client
           ^^^^^^^^^^^^^^^^^^^^
  File "/usr/local/lib/python3.12/functools.py", line 998, in __get__
    val = self.func(instance)
          ^^^^^^^^^^^^^^^^^^^
  File "/home/airflow/.local/lib/python3.12/site-packages/airflow/providers/docker/hooks/docker.py", line 161, in api_client
    raise AirflowException("Failed to establish connection to any given Docker hosts.")
airflow.exceptions.AirflowException: Failed to establish connection to any given Docker hosts.
[2025-02-21T13:39:38.040+0000] {taskinstance.py:1226} INFO - Marking task as UP_FOR_RETRY. dag_id=ing_mov_20_21, task_id=run_spark_script, run_id=manual__2025-02-21T13:39:36.308237+00:00, execution_date=20250221T133936, start_date=20250221T133937, end_date=20250221T133938
[2025-02-21T13:39:38.072+0000] {taskinstance.py:341} INFO - ::group::Post task execution logs
[2025-02-21T13:39:38.073+0000] {standard_task_runner.py:124} ERROR - Failed to execute job 9 for task run_spark_script (Failed to establish connection to any given Docker hosts.; 199)
Traceback (most recent call last):
  File "/home/airflow/.local/lib/python3.12/site-packages/airflow/task/task_runner/standard_task_runner.py", line 117, in _start_by_fork
    ret = args.func(args, dag=self.dag)
          ^^^^^^^^^^^^^^^^^^^^^^^^^^^^^
  File "/home/airflow/.local/lib/python3.12/site-packages/airflow/cli/cli_config.py", line 49, in command
    return func(*args, **kwargs)
           ^^^^^^^^^^^^^^^^^^^^^
  File "/home/airflow/.local/lib/python3.12/site-packages/airflow/utils/cli.py", line 116, in wrapper
    return f(*args, **kwargs)
           ^^^^^^^^^^^^^^^^^^
  File "/home/airflow/.local/lib/python3.12/site-packages/airflow/cli/commands/task_command.py", line 483, in task_run
    task_return_code = _run_task_by_selected_method(args, _dag, ti)
                       ^^^^^^^^^^^^^^^^^^^^^^^^^^^^^^^^^^^^^^^^^^^^
  File "/home/airflow/.local/lib/python3.12/site-packages/airflow/cli/commands/task_command.py", line 256, in _run_task_by_selected_method
    return _run_raw_task(args, ti)
           ^^^^^^^^^^^^^^^^^^^^^^^
  File "/home/airflow/.local/lib/python3.12/site-packages/airflow/cli/commands/task_command.py", line 341, in _run_raw_task
    return ti._run_raw_task(
           ^^^^^^^^^^^^^^^^^
  File "/home/airflow/.local/lib/python3.12/site-packages/airflow/utils/session.py", line 97, in wrapper
    return func(*args, session=session, **kwargs)
           ^^^^^^^^^^^^^^^^^^^^^^^^^^^^^^^^^^^^^^
  File "/home/airflow/.local/lib/python3.12/site-packages/airflow/models/taskinstance.py", line 3006, in _run_raw_task
    return _run_raw_task(
           ^^^^^^^^^^^^^^
  File "/home/airflow/.local/lib/python3.12/site-packages/airflow/models/taskinstance.py", line 274, in _run_raw_task
    TaskInstance._execute_task_with_callbacks(
  File "/home/airflow/.local/lib/python3.12/site-packages/airflow/models/taskinstance.py", line 3161, in _execute_task_with_callbacks
    result = self._execute_task(context, task_orig)
             ^^^^^^^^^^^^^^^^^^^^^^^^^^^^^^^^^^^^^^
  File "/home/airflow/.local/lib/python3.12/site-packages/airflow/models/taskinstance.py", line 3185, in _execute_task
    return _execute_task(self, context, task_orig)
           ^^^^^^^^^^^^^^^^^^^^^^^^^^^^^^^^^^^^^^^
  File "/home/airflow/.local/lib/python3.12/site-packages/airflow/models/taskinstance.py", line 768, in _execute_task
    result = _execute_callable(context=context, **execute_callable_kwargs)
             ^^^^^^^^^^^^^^^^^^^^^^^^^^^^^^^^^^^^^^^^^^^^^^^^^^^^^^^^^^^^^
  File "/home/airflow/.local/lib/python3.12/site-packages/airflow/models/taskinstance.py", line 734, in _execute_callable
    return ExecutionCallableRunner(
           ^^^^^^^^^^^^^^^^^^^^^^^^
  File "/home/airflow/.local/lib/python3.12/site-packages/airflow/utils/operator_helpers.py", line 252, in run
    return self.func(*args, **kwargs)
           ^^^^^^^^^^^^^^^^^^^^^^^^^^
  File "/home/airflow/.local/lib/python3.12/site-packages/airflow/models/baseoperator.py", line 424, in wrapper
    return func(self, *args, **kwargs)
           ^^^^^^^^^^^^^^^^^^^^^^^^^^^
  File "/home/airflow/.local/lib/python3.12/site-packages/airflow/providers/docker/operators/docker.py", line 467, in execute
    if self.force_pull or not self.cli.images(name=self.image):
                              ^^^^^^^^
  File "/home/airflow/.local/lib/python3.12/site-packages/airflow/providers/docker/operators/docker.py", line 341, in cli
    return self.hook.api_client
           ^^^^^^^^^^^^^^^^^^^^
  File "/usr/local/lib/python3.12/functools.py", line 998, in __get__
    val = self.func(instance)
          ^^^^^^^^^^^^^^^^^^^
  File "/home/airflow/.local/lib/python3.12/site-packages/airflow/providers/docker/hooks/docker.py", line 161, in api_client
    raise AirflowException("Failed to establish connection to any given Docker hosts.")
airflow.exceptions.AirflowException: Failed to establish connection to any given Docker hosts.
[2025-02-21T13:39:38.116+0000] {local_task_job_runner.py:266} INFO - Task exited with return code 1
[2025-02-21T13:39:38.136+0000] {taskinstance.py:3901} INFO - 0 downstream tasks scheduled from follow-on schedule check
[2025-02-21T13:39:38.137+0000] {local_task_job_runner.py:245} INFO - ::endgroup::
