[2025-02-21T13:48:40.720+0000] {local_task_job_runner.py:123} INFO - ::group::Pre task execution logs
[2025-02-21T13:48:40.739+0000] {taskinstance.py:2614} INFO - Dependencies all met for dep_context=non-requeueable deps ti=<TaskInstance: ing_mov_20_21.run_spark_script manual__2025-02-21T13:43:37.784214+00:00 [queued]>
[2025-02-21T13:48:40.747+0000] {taskinstance.py:2614} INFO - Dependencies all met for dep_context=requeueable deps ti=<TaskInstance: ing_mov_20_21.run_spark_script manual__2025-02-21T13:43:37.784214+00:00 [queued]>
[2025-02-21T13:48:40.748+0000] {taskinstance.py:2867} INFO - Starting attempt 2 of 2
[2025-02-21T13:48:40.760+0000] {taskinstance.py:2890} INFO - Executing <Task(DockerOperator): run_spark_script> on 2025-02-21 13:43:37.784214+00:00
[2025-02-21T13:48:40.764+0000] {warnings.py:112} WARNING - /home/***/.local/lib/python3.12/site-packages/***/task/task_runner/standard_task_runner.py:70: DeprecationWarning: This process (pid=114) is multi-threaded, use of fork() may lead to deadlocks in the child.
  pid = os.fork()

[2025-02-21T13:48:40.766+0000] {standard_task_runner.py:72} INFO - Started process 115 to run task
[2025-02-21T13:48:40.766+0000] {standard_task_runner.py:104} INFO - Running: ['***', 'tasks', 'run', 'ing_mov_20_21', 'run_spark_script', 'manual__2025-02-21T13:43:37.784214+00:00', '--job-id', '17', '--raw', '--subdir', 'DAGS_FOLDER/scriptteste.py', '--cfg-path', '/tmp/tmppquyzbt1']
[2025-02-21T13:48:40.767+0000] {standard_task_runner.py:105} INFO - Job 17: Subtask run_spark_script
[2025-02-21T13:48:40.818+0000] {task_command.py:467} INFO - Running <TaskInstance: ing_mov_20_21.run_spark_script manual__2025-02-21T13:43:37.784214+00:00 [running]> on host 7ae988a56c6e
[2025-02-21T13:48:40.893+0000] {taskinstance.py:3134} INFO - Exporting env vars: AIRFLOW_CTX_DAG_OWNER='***' AIRFLOW_CTX_DAG_ID='ing_mov_20_21' AIRFLOW_CTX_TASK_ID='run_spark_script' AIRFLOW_CTX_EXECUTION_DATE='2025-02-21T13:43:37.784214+00:00' AIRFLOW_CTX_TRY_NUMBER='2' AIRFLOW_CTX_DAG_RUN_ID='manual__2025-02-21T13:43:37.784214+00:00'
[2025-02-21T13:48:40.894+0000] {taskinstance.py:732} INFO - ::endgroup::
[2025-02-21T13:48:40.927+0000] {docker.py:468} INFO - ::group::Pulling docker image nome-da-sua-imagem-customizada
[2025-02-21T13:48:42.097+0000] {taskinstance.py:3313} ERROR - Task failed with exception
Traceback (most recent call last):
  File "/home/airflow/.local/lib/python3.12/site-packages/docker/api/client.py", line 275, in _raise_for_status
    response.raise_for_status()
  File "/home/airflow/.local/lib/python3.12/site-packages/requests/models.py", line 1024, in raise_for_status
    raise HTTPError(http_error_msg, response=self)
requests.exceptions.HTTPError: 404 Client Error: Not Found for url: http+docker://localhost/v1.47/images/create?tag=latest&fromImage=nome-da-sua-imagem-customizada

The above exception was the direct cause of the following exception:

Traceback (most recent call last):
  File "/home/airflow/.local/lib/python3.12/site-packages/airflow/models/taskinstance.py", line 768, in _execute_task
    result = _execute_callable(context=context, **execute_callable_kwargs)
             ^^^^^^^^^^^^^^^^^^^^^^^^^^^^^^^^^^^^^^^^^^^^^^^^^^^^^^^^^^^^^
  File "/home/airflow/.local/lib/python3.12/site-packages/airflow/models/taskinstance.py", line 734, in _execute_callable
    return ExecutionCallableRunner(
           ^^^^^^^^^^^^^^^^^^^^^^^^
  File "/home/airflow/.local/lib/python3.12/site-packages/airflow/utils/operator_helpers.py", line 252, in run
    return self.func(*args, **kwargs)
           ^^^^^^^^^^^^^^^^^^^^^^^^^^
  File "/home/airflow/.local/lib/python3.12/site-packages/airflow/models/baseoperator.py", line 424, in wrapper
    return func(self, *args, **kwargs)
           ^^^^^^^^^^^^^^^^^^^^^^^^^^^
  File "/home/airflow/.local/lib/python3.12/site-packages/airflow/providers/docker/operators/docker.py", line 470, in execute
    for output in self.cli.pull(self.image, stream=True, decode=True):
                  ^^^^^^^^^^^^^^^^^^^^^^^^^^^^^^^^^^^^^^^^^^^^^^^^^^^
  File "/home/airflow/.local/lib/python3.12/site-packages/docker/api/image.py", line 429, in pull
    self._raise_for_status(response)
  File "/home/airflow/.local/lib/python3.12/site-packages/docker/api/client.py", line 277, in _raise_for_status
    raise create_api_error_from_http_exception(e) from e
          ^^^^^^^^^^^^^^^^^^^^^^^^^^^^^^^^^^^^^^^
  File "/home/airflow/.local/lib/python3.12/site-packages/docker/errors.py", line 39, in create_api_error_from_http_exception
    raise cls(e, response=response, explanation=explanation) from e
docker.errors.ImageNotFound: 404 Client Error for http+docker://localhost/v1.47/images/create?tag=latest&fromImage=nome-da-sua-imagem-customizada: Not Found ("pull access denied for nome-da-sua-imagem-customizada, repository does not exist or may require 'docker login'")
[2025-02-21T13:48:42.108+0000] {taskinstance.py:1226} INFO - Marking task as FAILED. dag_id=ing_mov_20_21, task_id=run_spark_script, run_id=manual__2025-02-21T13:43:37.784214+00:00, execution_date=20250221T134337, start_date=20250221T134840, end_date=20250221T134842
[2025-02-21T13:48:42.137+0000] {taskinstance.py:341} INFO - ::group::Post task execution logs
[2025-02-21T13:48:42.138+0000] {standard_task_runner.py:124} ERROR - Failed to execute job 17 for task run_spark_script (404 Client Error for http+docker://localhost/v1.47/images/create?tag=latest&fromImage=nome-da-sua-imagem-customizada: Not Found ("pull access denied for nome-da-sua-imagem-customizada, repository does not exist or may require 'docker login'"); 115)
Traceback (most recent call last):
  File "/home/airflow/.local/lib/python3.12/site-packages/docker/api/client.py", line 275, in _raise_for_status
    response.raise_for_status()
  File "/home/airflow/.local/lib/python3.12/site-packages/requests/models.py", line 1024, in raise_for_status
    raise HTTPError(http_error_msg, response=self)
requests.exceptions.HTTPError: 404 Client Error: Not Found for url: http+docker://localhost/v1.47/images/create?tag=latest&fromImage=nome-da-sua-imagem-customizada

The above exception was the direct cause of the following exception:

Traceback (most recent call last):
  File "/home/airflow/.local/lib/python3.12/site-packages/airflow/task/task_runner/standard_task_runner.py", line 117, in _start_by_fork
    ret = args.func(args, dag=self.dag)
          ^^^^^^^^^^^^^^^^^^^^^^^^^^^^^
  File "/home/airflow/.local/lib/python3.12/site-packages/airflow/cli/cli_config.py", line 49, in command
    return func(*args, **kwargs)
           ^^^^^^^^^^^^^^^^^^^^^
  File "/home/airflow/.local/lib/python3.12/site-packages/airflow/utils/cli.py", line 116, in wrapper
    return f(*args, **kwargs)
           ^^^^^^^^^^^^^^^^^^
  File "/home/airflow/.local/lib/python3.12/site-packages/airflow/cli/commands/task_command.py", line 483, in task_run
    task_return_code = _run_task_by_selected_method(args, _dag, ti)
                       ^^^^^^^^^^^^^^^^^^^^^^^^^^^^^^^^^^^^^^^^^^^^
  File "/home/airflow/.local/lib/python3.12/site-packages/airflow/cli/commands/task_command.py", line 256, in _run_task_by_selected_method
    return _run_raw_task(args, ti)
           ^^^^^^^^^^^^^^^^^^^^^^^
  File "/home/airflow/.local/lib/python3.12/site-packages/airflow/cli/commands/task_command.py", line 341, in _run_raw_task
    return ti._run_raw_task(
           ^^^^^^^^^^^^^^^^^
  File "/home/airflow/.local/lib/python3.12/site-packages/airflow/utils/session.py", line 97, in wrapper
    return func(*args, session=session, **kwargs)
           ^^^^^^^^^^^^^^^^^^^^^^^^^^^^^^^^^^^^^^
  File "/home/airflow/.local/lib/python3.12/site-packages/airflow/models/taskinstance.py", line 3006, in _run_raw_task
    return _run_raw_task(
           ^^^^^^^^^^^^^^
  File "/home/airflow/.local/lib/python3.12/site-packages/airflow/models/taskinstance.py", line 274, in _run_raw_task
    TaskInstance._execute_task_with_callbacks(
  File "/home/airflow/.local/lib/python3.12/site-packages/airflow/models/taskinstance.py", line 3161, in _execute_task_with_callbacks
    result = self._execute_task(context, task_orig)
             ^^^^^^^^^^^^^^^^^^^^^^^^^^^^^^^^^^^^^^
  File "/home/airflow/.local/lib/python3.12/site-packages/airflow/models/taskinstance.py", line 3185, in _execute_task
    return _execute_task(self, context, task_orig)
           ^^^^^^^^^^^^^^^^^^^^^^^^^^^^^^^^^^^^^^^
  File "/home/airflow/.local/lib/python3.12/site-packages/airflow/models/taskinstance.py", line 768, in _execute_task
    result = _execute_callable(context=context, **execute_callable_kwargs)
             ^^^^^^^^^^^^^^^^^^^^^^^^^^^^^^^^^^^^^^^^^^^^^^^^^^^^^^^^^^^^^
  File "/home/airflow/.local/lib/python3.12/site-packages/airflow/models/taskinstance.py", line 734, in _execute_callable
    return ExecutionCallableRunner(
           ^^^^^^^^^^^^^^^^^^^^^^^^
  File "/home/airflow/.local/lib/python3.12/site-packages/airflow/utils/operator_helpers.py", line 252, in run
    return self.func(*args, **kwargs)
           ^^^^^^^^^^^^^^^^^^^^^^^^^^
  File "/home/airflow/.local/lib/python3.12/site-packages/airflow/models/baseoperator.py", line 424, in wrapper
    return func(self, *args, **kwargs)
           ^^^^^^^^^^^^^^^^^^^^^^^^^^^
  File "/home/airflow/.local/lib/python3.12/site-packages/airflow/providers/docker/operators/docker.py", line 470, in execute
    for output in self.cli.pull(self.image, stream=True, decode=True):
                  ^^^^^^^^^^^^^^^^^^^^^^^^^^^^^^^^^^^^^^^^^^^^^^^^^^^
  File "/home/airflow/.local/lib/python3.12/site-packages/docker/api/image.py", line 429, in pull
    self._raise_for_status(response)
  File "/home/airflow/.local/lib/python3.12/site-packages/docker/api/client.py", line 277, in _raise_for_status
    raise create_api_error_from_http_exception(e) from e
          ^^^^^^^^^^^^^^^^^^^^^^^^^^^^^^^^^^^^^^^
  File "/home/airflow/.local/lib/python3.12/site-packages/docker/errors.py", line 39, in create_api_error_from_http_exception
    raise cls(e, response=response, explanation=explanation) from e
docker.errors.ImageNotFound: 404 Client Error for http+docker://localhost/v1.47/images/create?tag=latest&fromImage=nome-da-sua-imagem-customizada: Not Found ("pull access denied for nome-da-sua-imagem-customizada, repository does not exist or may require 'docker login'")
[2025-02-21T13:48:42.185+0000] {local_task_job_runner.py:266} INFO - Task exited with return code 1
[2025-02-21T13:48:42.200+0000] {taskinstance.py:3901} INFO - 0 downstream tasks scheduled from follow-on schedule check
[2025-02-21T13:48:42.202+0000] {local_task_job_runner.py:245} INFO - ::endgroup::
